Traceback (most recent call last):
  File "/Users/rune/Documents/IN-KU/Teaching/Computational Neuroscience/Book/CompNeuroCourse2025/CompNeuroCourse/path_you_picked/compneurocourse/lib/python3.11/site-packages/myst_nb/core/execute/inline.py", line 128, in code_cell_outputs
    self._client.execute_cell(
  File "/Users/rune/Documents/IN-KU/Teaching/Computational Neuroscience/Book/CompNeuroCourse2025/CompNeuroCourse/path_you_picked/compneurocourse/lib/python3.11/site-packages/jupyter_core/utils/__init__.py", line 165, in wrapped
    return loop.run_until_complete(inner)
           ^^^^^^^^^^^^^^^^^^^^^^^^^^^^^^
  File "/opt/anaconda3/lib/python3.11/asyncio/base_events.py", line 653, in run_until_complete
    return future.result()
           ^^^^^^^^^^^^^^^
  File "/Users/rune/Documents/IN-KU/Teaching/Computational Neuroscience/Book/CompNeuroCourse2025/CompNeuroCourse/path_you_picked/compneurocourse/lib/python3.11/site-packages/nbclient/client.py", line 1062, in async_execute_cell
    await self._check_raise_for_error(cell, cell_index, exec_reply)
  File "/Users/rune/Documents/IN-KU/Teaching/Computational Neuroscience/Book/CompNeuroCourse2025/CompNeuroCourse/path_you_picked/compneurocourse/lib/python3.11/site-packages/nbclient/client.py", line 918, in _check_raise_for_error
    raise CellExecutionError.from_cell_and_msg(cell, exec_reply_content)
nbclient.exceptions.CellExecutionError: An error occurred while executing the following cell:
------------------
5*amp+10*volt
------------------


[31m---------------------------------------------------------------------------[39m
[31mDimensionMismatchError[39m                    Traceback (most recent call last)
[36mCell[39m[36m [39m[32mIn[7][39m[32m, line 1[39m
[32m----> [39m[32m1[39m [32;43m5[39;49m[43m*[49m[43mamp[49m[43m+[49m[32;43m10[39;49m[43m*[49m[43mvolt[49m

[36mFile [39m[32m~/Documents/IN-KU/Teaching/Computational Neuroscience/Book/CompNeuroCourse2025/CompNeuroCourse/path_you_picked/compneurocourse/lib/python3.11/site-packages/brian2/units/fundamentalunits.py:1193[39m, in [36mQuantity.__array_ufunc__[39m[34m(self, uf, method, *inputs, **kwargs)[39m
[32m   1190[39m [38;5;28;01melif[39;00m uf.[34m__name__[39m [38;5;129;01min[39;00m UFUNCS_MATCHING_DIMENSIONS + UFUNCS_COMPARISONS:
[32m   1191[39m     [38;5;66;03m# Ok if dimension of arguments match (for reductions, they always do)[39;00m
[32m   1192[39m     [38;5;28;01mif[39;00m method == [33m"[39m[33m__call__[39m[33m"[39m:
[32m-> [39m[32m1193[39m         [43mfail_for_dimension_mismatch[49m[43m([49m
[32m   1194[39m [43m            [49m[43minputs[49m[43m[[49m[32;43m0[39;49m[43m][49m[43m,[49m
[32m   1195[39m [43m            [49m[43minputs[49m[43m[[49m[32;43m1[39;49m[43m][49m[43m,[49m
[32m   1196[39m [43m            [49m[43merror_message[49m[43m=[49m[43m([49m
[32m   1197[39m [43m                [49m[33;43m"[39;49m[33;43mCannot calculate [39;49m[38;5;132;43;01m{val1}[39;49;00m[33;43m [39;49m[38;5;132;43;01m%s[39;49;00m[33;43m [39;49m[38;5;132;43;01m{val2}[39;49;00m[33;43m, the units do not match[39;49m[33;43m"[39;49m
[32m   1198[39m [43m            [49m[43m)[49m
[32m   1199[39m [43m            [49m[43m%[49m[43m [49m[43muf[49m[43m.[49m[34;43m__name__[39;49m[43m,[49m
[32m   1200[39m [43m            [49m[43mval1[49m[43m=[49m[43minputs[49m[43m[[49m[32;43m0[39;49m[43m][49m[43m,[49m
[32m   1201[39m [43m            [49m[43mval2[49m[43m=[49m[43minputs[49m[43m[[49m[32;43m1[39;49m[43m][49m[43m,[49m
[32m   1202[39m [43m        [49m[43m)[49m
[32m   1203[39m     [38;5;28;01mif[39;00m uf.[34m__name__[39m [38;5;129;01min[39;00m UFUNCS_COMPARISONS:
[32m   1204[39m         [38;5;28;01mreturn[39;00m uf_method(*[np.asarray(i) [38;5;28;01mfor[39;00m i [38;5;129;01min[39;00m inputs], **kwargs)

[36mFile [39m[32m~/Documents/IN-KU/Teaching/Computational Neuroscience/Book/CompNeuroCourse2025/CompNeuroCourse/path_you_picked/compneurocourse/lib/python3.11/site-packages/brian2/units/fundamentalunits.py:266[39m, in [36mfail_for_dimension_mismatch[39m[34m(obj1, obj2, error_message, **error_quantities)[39m
[32m    264[39m         [38;5;28;01mraise[39;00m DimensionMismatchError(error_message, dim1)
[32m    265[39m     [38;5;28;01melse[39;00m:
[32m--> [39m[32m266[39m         [38;5;28;01mraise[39;00m DimensionMismatchError(error_message, dim1, dim2)
[32m    267[39m [38;5;28;01melse[39;00m:
[32m    268[39m     [38;5;28;01mreturn[39;00m dim1, dim2

[31mDimensionMismatchError[39m: Cannot calculate 5. A add 10. V, the units do not match (units are A and V).

