Traceback (most recent call last):
  File "C:\Users\jhc23\AppData\Local\Programs\Python\Python312\Lib\site-packages\myst_nb\core\execute\inline.py", line 128, in code_cell_outputs
    self._client.execute_cell(
  File "C:\Users\jhc23\AppData\Roaming\Python\Python312\site-packages\jupyter_core\utils\__init__.py", line 165, in wrapped
    return loop.run_until_complete(inner)
           ^^^^^^^^^^^^^^^^^^^^^^^^^^^^^^
  File "C:\Users\jhc23\AppData\Local\Programs\Python\Python312\Lib\asyncio\base_events.py", line 686, in run_until_complete
    return future.result()
           ^^^^^^^^^^^^^^^
  File "C:\Users\jhc23\AppData\Local\Programs\Python\Python312\Lib\site-packages\nbclient\client.py", line 1062, in async_execute_cell
    await self._check_raise_for_error(cell, cell_index, exec_reply)
  File "C:\Users\jhc23\AppData\Local\Programs\Python\Python312\Lib\site-packages\nbclient\client.py", line 918, in _check_raise_for_error
    raise CellExecutionError.from_cell_and_msg(cell, exec_reply_content)
nbclient.exceptions.CellExecutionError: An error occurred while executing the following cell:
------------------
import brian2
------------------


[1;31m---------------------------------------------------------------------------[0m
[1;31mModuleNotFoundError[0m                       Traceback (most recent call last)
Cell [1;32mIn[6], line 1[0m
[1;32m----> 1[0m [38;5;28;01mimport[39;00m [38;5;21;01mbrian2[39;00m

[1;31mModuleNotFoundError[0m: No module named 'brian2'

