Traceback (most recent call last):
  File "/opt/anaconda3/lib/python3.11/site-packages/myst_nb/core/execute/inline.py", line 128, in code_cell_outputs
    self._client.execute_cell(
  File "/opt/anaconda3/lib/python3.11/site-packages/jupyter_core/utils/__init__.py", line 173, in wrapped
    return loop.run_until_complete(inner)
           ^^^^^^^^^^^^^^^^^^^^^^^^^^^^^^
  File "/opt/anaconda3/lib/python3.11/asyncio/base_events.py", line 653, in run_until_complete
    return future.result()
           ^^^^^^^^^^^^^^^
  File "/opt/anaconda3/lib/python3.11/site-packages/nbclient/client.py", line 1058, in async_execute_cell
    await self._check_raise_for_error(cell, cell_index, exec_reply)
  File "/opt/anaconda3/lib/python3.11/site-packages/nbclient/client.py", line 914, in _check_raise_for_error
    raise CellExecutionError.from_cell_and_msg(cell, exec_reply_content)
nbclient.exceptions.CellExecutionError: An error occurred while executing the following cell:
------------------
x = 1
y = 4
z = y/(1-x)
------------------


[0;31m---------------------------------------------------------------------------[0m
[0;31mZeroDivisionError[0m                         Traceback (most recent call last)
Cell [0;32mIn[12], line 3[0m
[1;32m      1[0m x [38;5;241m=[39m [38;5;241m1[39m
[1;32m      2[0m y [38;5;241m=[39m [38;5;241m4[39m
[0;32m----> 3[0m z [38;5;241m=[39m y[38;5;241m/[39m([38;5;241m1[39m[38;5;241m-[39mx)

[0;31mZeroDivisionError[0m: division by zero

