Traceback (most recent call last):
  File "/opt/anaconda3/lib/python3.11/site-packages/myst_nb/core/execute/inline.py", line 128, in code_cell_outputs
    self._client.execute_cell(
  File "/opt/anaconda3/lib/python3.11/site-packages/jupyter_core/utils/__init__.py", line 173, in wrapped
    return loop.run_until_complete(inner)
           ^^^^^^^^^^^^^^^^^^^^^^^^^^^^^^
  File "/opt/anaconda3/lib/python3.11/asyncio/base_events.py", line 653, in run_until_complete
    return future.result()
           ^^^^^^^^^^^^^^^
  File "/opt/anaconda3/lib/python3.11/site-packages/nbclient/client.py", line 1058, in async_execute_cell
    await self._check_raise_for_error(cell, cell_index, exec_reply)
  File "/opt/anaconda3/lib/python3.11/site-packages/nbclient/client.py", line 914, in _check_raise_for_error
    raise CellExecutionError.from_cell_and_msg(cell, exec_reply_content)
nbclient.exceptions.CellExecutionError: An error occurred while executing the following cell:
------------------
from scipy import linalg

C_inverse = linalg.inv(C)
print(C_inverse)

## Your solution here
------------------


[0;31m---------------------------------------------------------------------------[0m
[0;31mNameError[0m                                 Traceback (most recent call last)
Cell [0;32mIn[12], line 3[0m
[1;32m      1[0m [38;5;28;01mfrom[39;00m [38;5;21;01mscipy[39;00m [38;5;28;01mimport[39;00m linalg
[0;32m----> 3[0m C_inverse [38;5;241m=[39m linalg[38;5;241m.[39minv(C)
[1;32m      4[0m [38;5;28mprint[39m(C_inverse)

[0;31mNameError[0m: name 'C' is not defined

