Traceback (most recent call last):
  File "/Users/rune/Documents/IN-KU/Teaching/Computational Neuroscience/Book/CompNeuroCourse2025/CompNeuroCourse/path_you_picked/compneurocourse/lib/python3.11/site-packages/myst_nb/core/execute/inline.py", line 128, in code_cell_outputs
    self._client.execute_cell(
  File "/Users/rune/Documents/IN-KU/Teaching/Computational Neuroscience/Book/CompNeuroCourse2025/CompNeuroCourse/path_you_picked/compneurocourse/lib/python3.11/site-packages/jupyter_core/utils/__init__.py", line 165, in wrapped
    return loop.run_until_complete(inner)
           ^^^^^^^^^^^^^^^^^^^^^^^^^^^^^^
  File "/opt/anaconda3/lib/python3.11/asyncio/base_events.py", line 653, in run_until_complete
    return future.result()
           ^^^^^^^^^^^^^^^
  File "/Users/rune/Documents/IN-KU/Teaching/Computational Neuroscience/Book/CompNeuroCourse2025/CompNeuroCourse/path_you_picked/compneurocourse/lib/python3.11/site-packages/nbclient/client.py", line 1062, in async_execute_cell
    await self._check_raise_for_error(cell, cell_index, exec_reply)
  File "/Users/rune/Documents/IN-KU/Teaching/Computational Neuroscience/Book/CompNeuroCourse2025/CompNeuroCourse/path_you_picked/compneurocourse/lib/python3.11/site-packages/nbclient/client.py", line 918, in _check_raise_for_error
    raise CellExecutionError.from_cell_and_msg(cell, exec_reply_content)
nbclient.exceptions.CellExecutionError: An error occurred while executing the following cell:
------------------
for item in sequence:
    # Do something with item
------------------


  [36mCell[39m[36m [39m[32mIn[1][39m[32m, line 2[39m
[31m    [39m[31m# Do something with item[39m
                            ^
[31mSyntaxError[39m[31m:[39m incomplete input


